2022-02-04 00:27:46,717 INFO    MainThread:8441 [internal.py:wandb_internal():89] W&B internal server running at pid: 8441, started at: 2022-02-04 00:27:46.714447
2022-02-04 00:27:46,721 INFO    WriterThread:8441 [datastore.py:open_for_write():77] open: /WAVE/users/unix/tpandey/wandb/run-20220204_002744-u36ujkv5/run-u36ujkv5.wandb
2022-02-04 00:27:46,722 DEBUG   HandlerThread:8441 [handler.py:handle_request():131] handle_request: check_version
2022-02-04 00:27:46,727 DEBUG   SenderThread:8441 [sender.py:send():235] send: header
2022-02-04 00:27:46,727 DEBUG   SenderThread:8441 [sender.py:send_request():249] send_request: check_version
2022-02-04 00:27:46,739 DEBUG   SenderThread:8441 [sender.py:send():235] send: run
2022-02-04 00:27:46,758 INFO    SenderThread:8441 [sender.py:_maybe_setup_resume():489] checking resume status for None/train/u36ujkv5
2022-02-04 00:27:50,242 ERROR   SenderThread:8441 [retry.py:__call__():126] Retry attempt failed:
Traceback (most recent call last):
  File "/WAVE/users/unix/tpandey/yolo-env/lib/python3.8/site-packages/urllib3/connection.py", line 174, in _new_conn
    conn = connection.create_connection(
  File "/WAVE/users/unix/tpandey/yolo-env/lib/python3.8/site-packages/urllib3/util/connection.py", line 95, in create_connection
    raise err
  File "/WAVE/users/unix/tpandey/yolo-env/lib/python3.8/site-packages/urllib3/util/connection.py", line 85, in create_connection
    sock.connect(sa)
ConnectionRefusedError: [Errno 111] Connection refused

During handling of the above exception, another exception occurred:

Traceback (most recent call last):
  File "/WAVE/users/unix/tpandey/yolo-env/lib/python3.8/site-packages/urllib3/connectionpool.py", line 703, in urlopen
    httplib_response = self._make_request(
  File "/WAVE/users/unix/tpandey/yolo-env/lib/python3.8/site-packages/urllib3/connectionpool.py", line 386, in _make_request
    self._validate_conn(conn)
  File "/WAVE/users/unix/tpandey/yolo-env/lib/python3.8/site-packages/urllib3/connectionpool.py", line 1040, in _validate_conn
    conn.connect()
  File "/WAVE/users/unix/tpandey/yolo-env/lib/python3.8/site-packages/urllib3/connection.py", line 358, in connect
    conn = self._new_conn()
  File "/WAVE/users/unix/tpandey/yolo-env/lib/python3.8/site-packages/urllib3/connection.py", line 186, in _new_conn
    raise NewConnectionError(
urllib3.exceptions.NewConnectionError: <urllib3.connection.HTTPSConnection object at 0x7ff7a4463460>: Failed to establish a new connection: [Errno 111] Connection refused

During handling of the above exception, another exception occurred:

Traceback (most recent call last):
  File "/WAVE/users/unix/tpandey/yolo-env/lib/python3.8/site-packages/requests/adapters.py", line 440, in send
    resp = conn.urlopen(
  File "/WAVE/users/unix/tpandey/yolo-env/lib/python3.8/site-packages/urllib3/connectionpool.py", line 785, in urlopen
    retries = retries.increment(
  File "/WAVE/users/unix/tpandey/yolo-env/lib/python3.8/site-packages/urllib3/util/retry.py", line 592, in increment
    raise MaxRetryError(_pool, url, error or ResponseError(cause))
urllib3.exceptions.MaxRetryError: HTTPSConnectionPool(host='api.wandb.ai', port=443): Max retries exceeded with url: /graphql (Caused by NewConnectionError('<urllib3.connection.HTTPSConnection object at 0x7ff7a4463460>: Failed to establish a new connection: [Errno 111] Connection refused'))

During handling of the above exception, another exception occurred:

Traceback (most recent call last):
  File "/WAVE/users/unix/tpandey/yolo-env/lib/python3.8/site-packages/wandb/sdk/lib/retry.py", line 102, in __call__
    result = self._call_fn(*args, **kwargs)
  File "/WAVE/users/unix/tpandey/yolo-env/lib/python3.8/site-packages/wandb/sdk/internal/internal_api.py", line 140, in execute
    return self.client.execute(*args, **kwargs)
  File "/WAVE/users/unix/tpandey/yolo-env/lib/python3.8/site-packages/wandb/vendor/gql-0.2.0/gql/client.py", line 52, in execute
    result = self._get_result(document, *args, **kwargs)
  File "/WAVE/users/unix/tpandey/yolo-env/lib/python3.8/site-packages/wandb/vendor/gql-0.2.0/gql/client.py", line 60, in _get_result
    return self.transport.execute(document, *args, **kwargs)
  File "/WAVE/users/unix/tpandey/yolo-env/lib/python3.8/site-packages/wandb/vendor/gql-0.2.0/gql/transport/requests.py", line 38, in execute
    request = requests.post(self.url, **post_args)
  File "/WAVE/users/unix/tpandey/yolo-env/lib/python3.8/site-packages/requests/api.py", line 117, in post
    return request('post', url, data=data, json=json, **kwargs)
  File "/WAVE/users/unix/tpandey/yolo-env/lib/python3.8/site-packages/requests/api.py", line 61, in request
    return session.request(method=method, url=url, **kwargs)
  File "/WAVE/users/unix/tpandey/yolo-env/lib/python3.8/site-packages/requests/sessions.py", line 529, in request
    resp = self.send(prep, **send_kwargs)
  File "/WAVE/users/unix/tpandey/yolo-env/lib/python3.8/site-packages/requests/sessions.py", line 645, in send
    r = adapter.send(request, **kwargs)
  File "/WAVE/users/unix/tpandey/yolo-env/lib/python3.8/site-packages/requests/adapters.py", line 519, in send
    raise ConnectionError(e, request=request)
requests.exceptions.ConnectionError: HTTPSConnectionPool(host='api.wandb.ai', port=443): Max retries exceeded with url: /graphql (Caused by NewConnectionError('<urllib3.connection.HTTPSConnection object at 0x7ff7a4463460>: Failed to establish a new connection: [Errno 111] Connection refused'))
2022-02-04 00:28:16,741 DEBUG   HandlerThread:8441 [handler.py:handle_request():131] handle_request: shutdown
2022-02-04 00:28:16,741 INFO    HandlerThread:8441 [handler.py:finish():739] shutting down handler
2022-02-04 00:28:16,776 INFO    WriterThread:8441 [datastore.py:close():281] close: /WAVE/users/unix/tpandey/wandb/run-20220204_002744-u36ujkv5/run-u36ujkv5.wandb
